Workbook

Sheet 使用说明
A1: 威胁建模安全评审评分模板（部门/团队/项目）
A3: 填写顺序
A4: 1 | B4: 先在【评分明细】逐条记录威胁项：部门、团队、项目、业务场景、架构场景、威胁类型与评分维度。
A5: 2 | B5: 评分维度使用 1-5 分：分值越高代表风险越高（控制成熟度、检测能力相反，分值越高代表能力越好）。
A6: 3 | B6: 业务场景系数、架构场景系数会自动从【场景库】匹配；找不到场景时默认系数 1。
A7: 4 | B7: 最终风险分自动计算；可在整改后风险分列手动填写复测结果。
A8: 5 | B8: 在【汇总看板】输入需要统计的部门/团队/项目名称，自动输出各维度评分与高风险数量。
A10: 评分口径（1-5）
A11: 资产等级 | B11: 1=低价值，5=核心资产（资金/核心交易/隐私敏感数据）。
A12: 暴露面 | B12: 1=仅内网可达，5=公网高频可达且入口复杂。
A13: 发生可能性 | B13: 1=很难触发，5=容易被脚本化利用。
A14: 影响程度 | B14: 1=影响很小，5=造成资金损失/大规模泄露/核心业务中断。
A15: 控制成熟度 | B15: 1=几乎无控制，5=控制完善并长期验证。
A16: 检测能力 | B16: 1=无监测与告警，5=秒级监测、自动告警与追踪。
A17: 合规敏感度 | B17: 0=无明确合规要求，5=强合规高处罚风险场景。
A19: 计算逻辑
A20: 基础风险分 | B20: ((资产*0.15 + 暴露面*0.15 + 可能性*0.25 + 影响*0.25 + 合规*0.10 + (6-控制成熟度)*0.05 + (6-检测能力)*0.05) / 5) * 100
A21: 加权风险分 | B21: MIN(100, 基础风险分 * 业务系数 * 架构系数)
A22: 安全评分 | B22: 100 - 最终风险分（分值越高越安全）
A23: 风险等级 | B23: 严重>=80，高>=60，中>=40，低<40
A25: 提示 | B25: 模板已预置示例数据，可直接覆盖。建议每个项目至少覆盖：鉴权、交易/资金、数据、第三方依赖、运维管理、审计监控六类威胁面。

Sheet 场景库
A1: 业务场景 | B1: 业务系数 | C1: 说明 | D1: 架构场景 | E1: 架构系数 | F1: 说明 | H1: 威胁类型库 | I1: 说明
A2: 用户注册/登录鉴权 | B2: 1.1 | C2: 身份认证、会话与账号安全 | D2: 单体应用 | E2: 1 | F2: 结构简单但边界可能模糊 | H2: 欺骗 (Spoofing) | I2: 伪造身份、令牌、证书、来源
A3: 支付下单结算 | B3: 1.25 | C3: 资金与交易核心链路 | D3: 微服务 | E3: 1.1 | F3: 服务间鉴权与调用链风险 | H3: 篡改 (Tampering) | I3: 交易、参数、配置、数据被修改
A4: 退款/退货 | B4: 1.2 | C4: 逆向资金流与业务逻辑风控 | D4: 事件驱动/消息队列 | E4: 1.1 | F4: 消息重放、丢失与一致性风险 | H4: 抵赖 (Repudiation) | I4: 行为不可追溯、审计证据不足
A5: 提现/转账 | B5: 1.3 | C5: 高风险资金出站场景 | D5: API网关+微服务 | E5: 1.15 | F5: 网关策略与后端信任边界 | H5: 信息泄露 (Information Disclosure) | I5: 敏感数据被未授权访问
A6: 营销活动/优惠券 | B6: 1.15 | C6: 防刷与规则绕过高发 | D6: Service Mesh | E6: 1.15 | F6: 证书、策略与服务间流量控制 | H6: 拒绝服务 (DoS) | I6: 资源耗尽、服务不可用
A7: 内容发布/评论 | B7: 1.05 | C7: 内容安全与权限边界 | D7: Serverless/FaaS | E7: 1.1 | F7: 函数权限与冷启动配置风险 | H7: 权限提升 (Elevation of Privilege) | I7: 低权限获得高权限操作
A8: 文件上传/下载 | B8: 1.15 | C8: 恶意文件与越权访问风险 | D8: Kubernetes容器编排 | E8: 1.15 | F8: 集群面、镜像与运行时风险 | H8: 供应链攻击 | I8: 依赖、镜像、SDK、第三方服务被投毒
A9: 实名认证/KYC | B9: 1.2 | C9: 隐私与合规敏感场景 | D9: 多云/混合云 | E9: 1.2 | F9: 跨云身份与网络边界复杂 | H9: 业务逻辑滥用 | I9: 规则绕过、套利、刷单、薅羊毛
A10: 第三方开放API | B10: 1.2 | C10: 接口滥用与调用链风险 | D10: 零信任接入 | E10: 1.1 | F10: 策略配置错误带来的可达性风险 | H10: 越权访问 | I10: 水平/垂直越权与对象访问控制缺陷
A11: B2B系统对接 | B11: 1.15 | C11: 跨组织边界与信任传递 | D11: 边缘计算节点 | E11: 1.2 | F11: 节点分散、物理与网络风险叠加 | H11: 配置与密钥泄露 | I11: 凭证管理不当导致系统失守
A12: 供应链协同 | B12: 1.1 | C12: 上下游权限与数据链路 | D12: 移动端+后端 | E12: 1.1 | F12: 端侧逆向与接口安全风险
A13: 运营后台管理 | B13: 1.2 | C13: 高权限后台与越权风险 | D13: 小程序架构 | E13: 1.05 | F13: 平台限制与鉴权复用风险
A14: 客服工单系统 | B14: 1.05 | C14: 社工与敏感信息暴露风险 | D14: Web+APP+开放平台 | E14: 1.2 | F14: 多端一致性与安全基线复杂
A15: 数据报表/BI | B15: 1.1 | C15: 聚合数据泄露与滥用 | D15: 数据湖/数仓 | E15: 1.15 | F15: 数据权限与脱敏治理风险
A16: 搜索推荐 | B16: 1.05 | C16: 数据污染与结果操控 | D16: 实时流处理 | E16: 1.15 | F16: 数据漂移与实时风控链路风险
A17: IoT设备接入 | B17: 1.2 | C17: 设备身份、固件与协议安全 | D17: 高并发缓存集群 | E17: 1.1 | F17: 缓存穿透与投毒风险
A18: 地图定位服务 | B18: 1.05 | C18: 地理数据与权限隔离 | D18: 分布式事务/最终一致性 | E18: 1.2 | F18: 补偿逻辑和重复执行风险
A19: 即时通讯/消息推送 | B19: 1.1 | C19: 消息篡改与伪造风险 | D19: 跨境多地域部署 | E19: 1.2 | F19: 数据主权与跨域合规要求
A20: 直播/音视频 | B20: 1.1 | C20: 内容、带宽与账号攻击 | D20: 区块链智能合约 | E20: 1.3 | F20: 不可变代码与链上资金风险
A21: 广告投放 | B21: 1.1 | C21: 作弊流量与结算欺诈 | D21: 第三方SaaS深度集成 | E21: 1.15 | F21: 供应链依赖与访问令牌风险
A22: 金融借贷 | B22: 1.35 | C22: 额度、授信与资金风险
A23: 保险理赔 | B23: 1.25 | C23: 欺诈与合规审计风险
A24: 医疗健康数据 | B24: 1.3 | C24: 高敏隐私与强监管
A25: AI模型推理服务 | B25: 1.15 | C25: 模型滥用与提示注入
A26: 多租户SaaS | B26: 1.2 | C26: 租户隔离与配置泄露
A27: 区块链资产服务 | B27: 1.35 | C27: 私钥、合约与链上交易风险
A30: 提示 | B30: 可按公司实际业务追加场景与系数；系数建议范围 0.9~1.5。

Sheet 评分明细
A1: 评审ID | B1: 评审日期 | C1: 所属部门 | D1: 所属团队 | E1: 所属项目 | F1: 业务场景 | G1: 架构场景 | H1: 威胁类型 | I1: 资产等级(1-5) | J1: 暴露面(1-5) | K1: 发生可能性(1-5) | L1: 影响程度(1-5) | M1: 控制成熟度(1-5,高=好) | N1: 检测能力(1-5,高=好) | O1: 合规敏感度(0-5) | P1: 基础风险分 | Q1: 业务系数 | R1: 架构系数 | S1: 加权风险分 | T1: 初始安全评分 | U1: 风险等级 | V1: 整改状态 | W1: 整改后风险分 | X1: 最终风险分 | Y1: 最终安全评分 | Z1: 备注
A2: TM-2026-001 | B2: 2026-02-23 | C2: 支付事业部 | D2: 交易平台组 | E2: 统一收银台 | F2: 支付下单结算 | G2: API网关+微服务 | H2: 权限提升 (Elevation of Privilege) | I2: 5 | J2: 4 | K2: 4 | L2: 5 | M2: 3 | N2: 3 | O2: 4 | P2: =IF(COUNTA(I2:O2)=0,"",ROUND((I2*0.15+J2*0.15+K2*0.25+L2*0.25+O2*0.1+(6-M2)*0.05+(6-N2)*0.05)/5*100,1)) -> 0 | Q2: =IF(F2="","",IFERROR(INDEX(场景库!$B:$B,MATCH(F2,场景库!$A:$A,0)),1)) -> 0 | R2: =IF(G2="","",IFERROR(INDEX(场景库!$E:$E,MATCH(G2,场景库!$D:$D,0)),1)) -> 0 | S2: =IF(P2="","",ROUND(MIN(100,P2*Q2*R2),1)) -> 0 | T2: =IF(S2="","",ROUND(100-S2,1)) -> 0 | U2: =IF(X2="","",IF(X2>=80,"严重",IF(X2>=60,"高",IF(X2>=40,"中","低")))) -> 0 | V2: 未整改 | X2: =IF(S2="","",IF(W2="",S2,W2)) -> 0 | Y2: =IF(X2="","",ROUND(100-X2,1)) -> 0 | Z2: 鉴权绕过可导致越权扣款
A3: TM-2026-002 | B3: 2026-02-23 | C3: 支付事业部 | D3: 清结算组 | E3: 退款中心 | F3: 退款/退货 | G3: 分布式事务/最终一致性 | H3: 抵赖 (Repudiation) | I3: 4 | J3: 3 | K3: 3 | L3: 4 | M3: 3 | N3: 2 | O3: 3 | P3: =IF(COUNTA(I3:O3)=0,"",ROUND((I3*0.15+J3*0.15+K3*0.25+L3*0.25+O3*0.1+(6-M3)*0.05+(6-N3)*0.05)/5*100,1)) -> 0 | Q3: =IF(F3="","",IFERROR(INDEX(场景库!$B:$B,MATCH(F3,场景库!$A:$A,0)),1)) -> 0 | R3: =IF(G3="","",IFERROR(INDEX(场景库!$E:$E,MATCH(G3,场景库!$D:$D,0)),1)) -> 0 | S3: =IF(P3="","",ROUND(MIN(100,P3*Q3*R3),1)) -> 0 | T3: =IF(S3="","",ROUND(100-S3,1)) -> 0 | U3: =IF(X3="","",IF(X3>=80,"严重",IF(X3>=60,"高",IF(X3>=40,"中","低")))) -> 0 | V3: 已整改 | W3: 48 | X3: =IF(S3="","",IF(W3="",S3,W3)) -> 0 | Y3: =IF(X3="","",ROUND(100-X3,1)) -> 0 | Z3: 补充签名流水与防重放后复测
A4: TM-2026-003 | B4: 2026-02-23 | C4: 增长事业部 | D4: 营销平台组 | E4: 优惠券引擎 | F4: 营销活动/优惠券 | G4: 微服务 | H4: 业务逻辑滥用 | I4: 3 | J4: 4 | K4: 5 | L4: 3 | M4: 2 | N4: 2 | O4: 2 | P4: =IF(COUNTA(I4:O4)=0,"",ROUND((I4*0.15+J4*0.15+K4*0.25+L4*0.25+O4*0.1+(6-M4)*0.05+(6-N4)*0.05)/5*100,1)) -> 0 | Q4: =IF(F4="","",IFERROR(INDEX(场景库!$B:$B,MATCH(F4,场景库!$A:$A,0)),1)) -> 0 | R4: =IF(G4="","",IFERROR(INDEX(场景库!$E:$E,MATCH(G4,场景库!$D:$D,0)),1)) -> 0 | S4: =IF(P4="","",ROUND(MIN(100,P4*Q4*R4),1)) -> 0 | T4: =IF(S4="","",ROUND(100-S4,1)) -> 0 | U4: =IF(X4="","",IF(X4>=80,"严重",IF(X4>=60,"高",IF(X4>=40,"中","低")))) -> 0 | V4: 未整改 | X4: =IF(S4="","",IF(W4="",S4,W4)) -> 0 | Y4: =IF(X4="","",ROUND(100-X4,1)) -> 0 | Z4: 存在批量刷券套利路径
A5: TM-2026-004 | B5: 2026-02-23 | C5: 数据平台主管 | D5: 数据基础组 | E5: 用户画像平台 | F5: 数据报表/BI | G5: 数据湖/数仓 | H5: 信息泄露 (Information Disclosure) | I5: 4 | J5: 4 | K5: 3 | L5: 5 | M5: 3 | N5: 3 | O5: 5 | P5: =IF(COUNTA(I5:O5)=0,"",ROUND((I5*0.15+J5*0.15+K5*0.25+L5*0.25+O5*0.1+(6-M5)*0.05+(6-N5)*0.05)/5*100,1)) -> 0 | Q5: =IF(F5="","",IFERROR(INDEX(场景库!$B:$B,MATCH(F5,场景库!$A:$A,0)),1)) -> 0 | R5: =IF(G5="","",IFERROR(INDEX(场景库!$E:$E,MATCH(G5,场景库!$D:$D,0)),1)) -> 0 | S5: =IF(P5="","",ROUND(MIN(100,P5*Q5*R5),1)) -> 0 | T5: =IF(S5="","",ROUND(100-S5,1)) -> 0 | U5: =IF(X5="","",IF(X5>=80,"严重",IF(X5>=60,"高",IF(X5>=40,"中","低")))) -> 0 | V5: 未整改 | X5: =IF(S5="","",IF(W5="",S5,W5)) -> 0 | Y5: =IF(X5="","",ROUND(100-X5,1)) -> 0 | Z5: PII 脱敏策略缺失
A6: TM-2026-005 | B6: 2026-02-23 | C6: 国际化平台主管 | D6: 开放平台组 | E6: B2B开放API | F6: 第三方开放API | G6: Web+APP+开放平台 | H6: 欺骗 (Spoofing) | I6: 4 | J6: 5 | K6: 4 | L6: 4 | M6: 2 | N6: 3 | O6: 3 | P6: =IF(COUNTA(I6:O6)=0,"",ROUND((I6*0.15+J6*0.15+K6*0.25+L6*0.25+O6*0.1+(6-M6)*0.05+(6-N6)*0.05)/5*100,1)) -> 0 | Q6: =IF(F6="","",IFERROR(INDEX(场景库!$B:$B,MATCH(F6,场景库!$A:$A,0)),1)) -> 0 | R6: =IF(G6="","",IFERROR(INDEX(场景库!$E:$E,MATCH(G6,场景库!$D:$D,0)),1)) -> 0 | S6: =IF(P6="","",ROUND(MIN(100,P6*Q6*R6),1)) -> 0 | T6: =IF(S6="","",ROUND(100-S6,1)) -> 0 | U6: =IF(X6="","",IF(X6>=80,"严重",IF(X6>=60,"高",IF(X6>=40,"中","低")))) -> 0 | V6: 未整改 | X6: =IF(S6="","",IF(W6="",S6,W6)) -> 0 | Y6: =IF(X6="","",ROUND(100-X6,1)) -> 0 | Z6: 缺少双向签名与重放保护
P7: =IF(COUNTA(I7:O7)=0,"",ROUND((I7*0.15+J7*0.15+K7*0.25+L7*0.25+O7*0.1+(6-M7)*0.05+(6-N7)*0.05)/5*100,1)) -> 0 | Q7: =IF(F7="","",IFERROR(INDEX(场景库!$B:$B,MATCH(F7,场景库!$A:$A,0)),1)) -> 0 | R7: =IF(G7="","",IFERROR(INDEX(场景库!$E:$E,MATCH(G7,场景库!$D:$D,0)),1)) -> 0 | S7: =IF(P7="","",ROUND(MIN(100,P7*Q7*R7),1)) -> 0 | T7: =IF(S7="","",ROUND(100-S7,1)) -> 0 | U7: =IF(X7="","",IF(X7>=80,"严重",IF(X7>=60,"高",IF(X7>=40,"中","低")))) -> 0 | X7: =IF(S7="","",IF(W7="",S7,W7)) -> 0 | Y7: =IF(X7="","",ROUND(100-X7,1)) -> 0
P8: =IF(COUNTA(I8:O8)=0,"",ROUND((I8*0.15+J8*0.15+K8*0.25+L8*0.25+O8*0.1+(6-M8)*0.05+(6-N8)*0.05)/5*100,1)) -> 0 | Q8: =IF(F8="","",IFERROR(INDEX(场景库!$B:$B,MATCH(F8,场景库!$A:$A,0)),1)) -> 0 | R8: =IF(G8="","",IFERROR(INDEX(场景库!$E:$E,MATCH(G8,场景库!$D:$D,0)),1)) -> 0 | S8: =IF(P8="","",ROUND(MIN(100,P8*Q8*R8),1)) -> 0 | T8: =IF(S8="","",ROUND(100-S8,1)) -> 0 | U8: =IF(X8="","",IF(X8>=80,"严重",IF(X8>=60,"高",IF(X8>=40,"中","低")))) -> 0 | X8: =IF(S8="","",IF(W8="",S8,W8)) -> 0 | Y8: =IF(X8="","",ROUND(100-X8,1)) -> 0
P9: =IF(COUNTA(I9:O9)=0,"",ROUND((I9*0.15+J9*0.15+K9*0.25+L9*0.25+O9*0.1+(6-M9)*0.05+(6-N9)*0.05)/5*100,1)) -> 0 | Q9: =IF(F9="","",IFERROR(INDEX(场景库!$B:$B,MATCH(F9,场景库!$A:$A,0)),1)) -> 0 | R9: =IF(G9="","",IFERROR(INDEX(场景库!$E:$E,MATCH(G9,场景库!$D:$D,0)),1)) -> 0 | S9: =IF(P9="","",ROUND(MIN(100,P9*Q9*R9),1)) -> 0 | T9: =IF(S9="","",ROUND(100-S9,1)) -> 0 | U9: =IF(X9="","",IF(X9>=80,"严重",IF(X9>=60,"高",IF(X9>=40,"中","低")))) -> 0 | X9: =IF(S9="","",IF(W9="",S9,W9)) -> 0 | Y9: =IF(X9="","",ROUND(100-X9,1)) -> 0
P10: =IF(COUNTA(I10:O10)=0,"",ROUND((I10*0.15+J10*0.15+K10*0.25+L10*0.25+O10*0.1+(6-M10)*0.05+(6-N10)*0.05)/5*100,1)) -> 0 | Q10: =IF(F10="","",IFERROR(INDEX(场景库!$B:$B,MATCH(F10,场景库!$A:$A,0)),1)) -> 0 | R10: =IF(G10="","",IFERROR(INDEX(场景库!$E:$E,MATCH(G10,场景库!$D:$D,0)),1)) -> 0 | S10: =IF(P10="","",ROUND(MIN(100,P10*Q10*R10),1)) -> 0 | T10: =IF(S10="","",ROUND(100-S10,1)) -> 0 | U10: =IF(X10="","",IF(X10>=80,"严重",IF(X10>=60,"高",IF(X10>=40,"中","低")))) -> 0 | X10: =IF(S10="","",IF(W10="",S10,W10)) -> 0 | Y10: =IF(X10="","",ROUND(100-X10,1)) -> 0
P11: =IF(COUNTA(I11:O11)=0,"",ROUND((I11*0.15+J11*0.15+K11*0.25+L11*0.25+O11*0.1+(6-M11)*0.05+(6-N11)*0.05)/5*100,1)) -> 0 | Q11: =IF(F11="","",IFERROR(INDEX(场景库!$B:$B,MATCH(F11,场景库!$A:$A,0)),1)) -> 0 | R11: =IF(G11="","",IFERROR(INDEX(场景库!$E:$E,MATCH(G11,场景库!$D:$D,0)),1)) -> 0 | S11: =IF(P11="","",ROUND(MIN(100,P11*Q11*R11),1)) -> 0 | T11: =IF(S11="","",ROUND(100-S11,1)) -> 0 | U11: =IF(X11="","",IF(X11>=80,"严重",IF(X11>=60,"高",IF(X11>=40,"中","低")))) -> 0 | X11: =IF(S11="","",IF(W11="",S11,W11)) -> 0 | Y11: =IF(X11="","",ROUND(100-X11,1)) -> 0
P12: =IF(COUNTA(I12:O12)=0,"",ROUND((I12*0.15+J12*0.15+K12*0.25+L12*0.25+O12*0.1+(6-M12)*0.05+(6-N12)*0.05)/5*100,1)) -> 0 | Q12: =IF(F12="","",IFERROR(INDEX(场景库!$B:$B,MATCH(F12,场景库!$A:$A,0)),1)) -> 0 | R12: =IF(G12="","",IFERROR(INDEX(场景库!$E:$E,MATCH(G12,场景库!$D:$D,0)),1)) -> 0 | S12: =IF(P12="","",ROUND(MIN(100,P12*Q12*R12),1)) -> 0 | T12: =IF(S12="","",ROUND(100-S12,1)) -> 0 | U12: =IF(X12="","",IF(X12>=80,"严重",IF(X12>=60,"高",IF(X12>=40,"中","低")))) -> 0 | X12: =IF(S12="","",IF(W12="",S12,W12)) -> 0 | Y12: =IF(X12="","",ROUND(100-X12,1)) -> 0
P13: =IF(COUNTA(I13:O13)=0,"",ROUND((I13*0.15+J13*0.15+K13*0.25+L13*0.25+O13*0.1+(6-M13)*0.05+(6-N13)*0.05)/5*100,1)) -> 0 | Q13: =IF(F13="","",IFERROR(INDEX(场景库!$B:$B,MATCH(F13,场景库!$A:$A,0)),1)) -> 0 | R13: =IF(G13="","",IFERROR(INDEX(场景库!$E:$E,MATCH(G13,场景库!$D:$D,0)),1)) -> 0 | S13: =IF(P13="","",ROUND(MIN(100,P13*Q13*R13),1)) -> 0 | T13: =IF(S13="","",ROUND(100-S13,1)) -> 0 | U13: =IF(X13="","",IF(X13>=80,"严重",IF(X13>=60,"高",IF(X13>=40,"中","低")))) -> 0 | X13: =IF(S13="","",IF(W13="",S13,W13)) -> 0 | Y13: =IF(X13="","",ROUND(100-X13,1)) -> 0
P14: =IF(COUNTA(I14:O14)=0,"",ROUND((I14*0.15+J14*0.15+K14*0.25+L14*0.25+O14*0.1+(6-M14)*0.05+(6-N14)*0.05)/5*100,1)) -> 0 | Q14: =IF(F14="","",IFERROR(INDEX(场景库!$B:$B,MATCH(F14,场景库!$A:$A,0)),1)) -> 0 | R14: =IF(G14="","",IFERROR(INDEX(场景库!$E:$E,MATCH(G14,场景库!$D:$D,0)),1)) -> 0 | S14: =IF(P14="","",ROUND(MIN(100,P14*Q14*R14),1)) -> 0 | T14: =IF(S14="","",ROUND(100-S14,1)) -> 0 | U14: =IF(X14="","",IF(X14>=80,"严重",IF(X14>=60,"高",IF(X14>=40,"中","低")))) -> 0 | X14: =IF(S14="","",IF(W14="",S14,W14)) -> 0 | Y14: =IF(X14="","",ROUND(100-X14,1)) -> 0
P15: =IF(COUNTA(I15:O15)=0,"",ROUND((I15*0.15+J15*0.15+K15*0.25+L15*0.25+O15*0.1+(6-M15)*0.05+(6-N15)*0.05)/5*100,1)) -> 0 | Q15: =IF(F15="","",IFERROR(INDEX(场景库!$B:$B,MATCH(F15,场景库!$A:$A,0)),1)) -> 0 | R15: =IF(G15="","",IFERROR(INDEX(场景库!$E:$E,MATCH(G15,场景库!$D:$D,0)),1)) -> 0 | S15: =IF(P15="","",ROUND(MIN(100,P15*Q15*R15),1)) -> 0 | T15: =IF(S15="","",ROUND(100-S15,1)) -> 0 | U15: =IF(X15="","",IF(X15>=80,"严重",IF(X15>=60,"高",IF(X15>=40,"中","低")))) -> 0 | X15: =IF(S15="","",IF(W15="",S15,W15)) -> 0 | Y15: =IF(X15="","",ROUND(100-X15,1)) -> 0
P16: =IF(COUNTA(I16:O16)=0,"",ROUND((I16*0.15+J16*0.15+K16*0.25+L16*0.25+O16*0.1+(6-M16)*0.05+(6-N16)*0.05)/5*100,1)) -> 0 | Q16: =IF(F16="","",IFERROR(INDEX(场景库!$B:$B,MATCH(F16,场景库!$A:$A,0)),1)) -> 0 | R16: =IF(G16="","",IFERROR(INDEX(场景库!$E:$E,MATCH(G16,场景库!$D:$D,0)),1)) -> 0 | S16: =IF(P16="","",ROUND(MIN(100,P16*Q16*R16),1)) -> 0 | T16: =IF(S16="","",ROUND(100-S16,1)) -> 0 | U16: =IF(X16="","",IF(X16>=80,"严重",IF(X16>=60,"高",IF(X16>=40,"中","低")))) -> 0 | X16: =IF(S16="","",IF(W16="",S16,W16)) -> 0 | Y16: =IF(X16="","",ROUND(100-X16,1)) -> 0
P17: =IF(COUNTA(I17:O17)=0,"",ROUND((I17*0.15+J17*0.15+K17*0.25+L17*0.25+O17*0.1+(6-M17)*0.05+(6-N17)*0.05)/5*100,1)) -> 0 | Q17: =IF(F17="","",IFERROR(INDEX(场景库!$B:$B,MATCH(F17,场景库!$A:$A,0)),1)) -> 0 | R17: =IF(G17="","",IFERROR(INDEX(场景库!$E:$E,MATCH(G17,场景库!$D:$D,0)),1)) -> 0 | S17: =IF(P17="","",ROUND(MIN(100,P17*Q17*R17),1)) -> 0 | T17: =IF(S17="","",ROUND(100-S17,1)) -> 0 | U17: =IF(X17="","",IF(X17>=80,"严重",IF(X17>=60,"高",IF(X17>=40,"中","低")))) -> 0 | X17: =IF(S17="","",IF(W17="",S17,W17)) -> 0 | Y17: =IF(X17="","",ROUND(100-X17,1)) -> 0
P18: =IF(COUNTA(I18:O18)=0,"",ROUND((I18*0.15+J18*0.15+K18*0.25+L18*0.25+O18*0.1+(6-M18)*0.05+(6-N18)*0.05)/5*100,1)) -> 0 | Q18: =IF(F18="","",IFERROR(INDEX(场景库!$B:$B,MATCH(F18,场景库!$A:$A,0)),1)) -> 0 | R18: =IF(G18="","",IFERROR(INDEX(场景库!$E:$E,MATCH(G18,场景库!$D:$D,0)),1)) -> 0 | S18: =IF(P18="","",ROUND(MIN(100,P18*Q18*R18),1)) -> 0 | T18: =IF(S18="","",ROUND(100-S18,1)) -> 0 | U18: =IF(X18="","",IF(X18>=80,"严重",IF(X18>=60,"高",IF(X18>=40,"中","低")))) -> 0 | X18: =IF(S18="","",IF(W18="",S18,W18)) -> 0 | Y18: =IF(X18="","",ROUND(100-X18,1)) -> 0
... P301: =IF(COUNTA(I301:O301)=0,"",ROUND((I301*0.15+J301*0.15+K301*0.25+L301*0.25+O301*0.1+(6-M301)*0.05+(6-N301)*0.05)/5*100,1)) -> 0 | Q301: =IF(F301="","",IFERROR(INDEX(场景库!$B:$B,MATCH(F301,场景库!$A:$A,0)),1)) -> 0 | R301: =IF(G301="","",IFERROR(INDEX(场景库!$E:$E,MATCH(G301,场景库!$D:$D,0)),1)) -> 0 | S301: =IF(P301="","",ROUND(MIN(100,P301*Q301*R301),1)) -> 0 | T301: =IF(S301="","",ROUND(100-S301,1)) -> 0 | U301: =IF(X301="","",IF(X301>=80,"严重",IF(X301>=60,"高",IF(X301>=40,"中","低")))) -> 0 | X301: =IF(S301="","",IF(W301="",S301,W301)) -> 0 | Y301: =IF(X301="","",ROUND(100-X301,1)) -> 0

Sheet 汇总看板
A1: 威胁建模评分汇总
A2: 提示：在部门/团队/项目汇总区域填入名称即可自动统计（支持按部门或团队筛选项目）。
A4: 全局指标
A5: 指标 | B5: 值
A6: 全局评审项数 | B6: =COUNTIFS(评分明细!$X:$X,"<>") -> 0
A7: 全局平均最终风险分 | B7: =IF(B6=0,"",ROUND(AVERAGEIFS(评分明细!$X:$X,评分明细!$X:$X,"<>"),1)) -> 0
A8: 全局平均安全评分 | B8: =IF(B7="","",ROUND(100-B7,1)) -> 0
A9: 全局高风险数(>=60) | B9: =COUNTIFS(评分明细!$X:$X,">=60") -> 0
A10: 全局严重风险数(>=80) | B10: =COUNTIFS(评分明细!$X:$X,">=80") -> 0
A12: 部门汇总 | H12: 团队汇总
A13: 部门 | B13: 评审项数 | C13: 平均最终风险分 | D13: 平均安全评分 | E13: 高风险数 | F13: 严重风险数 | H13: 团队 | I13: 部门(可选) | J13: 评审项数 | K13: 平均最终风险分 | L13: 平均安全评分 | M13: 高风险数 | N13: 严重风险数
A14: 支付事业部 | B14: =IF(A14="","",COUNTIFS(评分明细!$C:$C,A14,评分明细!$X:$X,"<>")) -> 0 | C14: =IF(B14=0,"",ROUND(AVERAGEIFS(评分明细!$X:$X,评分明细!$C:$C,A14,评分明细!$X:$X,"<>"),1)) -> 0 | D14: =IF(C14="","",ROUND(100-C14,1)) -> 0 | E14: =IF(B14=0,"",COUNTIFS(评分明细!$C:$C,A14,评分明细!$X:$X,">=60")) -> 0 | F14: =IF(B14=0,"",COUNTIFS(评分明细!$C:$C,A14,评分明细!$X:$X,">=80")) -> 0 | H14: 交易平台组 | I14: 支付事业部 | J14: =IF(H14="","",IF(I14="",COUNTIFS(评分明细!$D:$D,H14,评分明细!$X:$X,"<>"),COUNTIFS(评分明细!$D:$D,H14,评分明细!$C:$C,I14,评分明细!$X:$X,"<>"))) -> 0 | K14: =IF(J14=0,"",IF(I14="",ROUND(AVERAGEIFS(评分明细!$X:$X,评分明细!$D:$D,H14,评分明细!$X:$X,"<>"),1),ROUND(AVERAGEIFS(评分明细!$X:$X,评分明细!$D:$D,H14,评分明细!$C:$C,I14,评分明细!$X:$X,"<>"),1))) -> 0 | L14: =IF(K14="","",ROUND(100-K14,1)) -> 0 | M14: =IF(J14=0,"",IF(I14="",COUNTIFS(评分明细!$D:$D,H14,评分明细!$X:$X,">=60"),COUNTIFS(评分明细!$D:$D,H14,评分明细!$C:$C,I14,评分明细!$X:$X,">=60"))) -> 0 | N14: =IF(J14=0,"",IF(I14="",COUNTIFS(评分明细!$D:$D,H14,评分明细!$X:$X,">=80"),COUNTIFS(评分明细!$D:$D,H14,评分明细!$C:$C,I14,评分明细!$X:$X,">=80"))) -> 0
A15: 增长事业部 | B15: =IF(A15="","",COUNTIFS(评分明细!$C:$C,A15,评分明细!$X:$X,"<>")) -> 0 | C15: =IF(B15=0,"",ROUND(AVERAGEIFS(评分明细!$X:$X,评分明细!$C:$C,A15,评分明细!$X:$X,"<>"),1)) -> 0 | D15: =IF(C15="","",ROUND(100-C15,1)) -> 0 | E15: =IF(B15=0,"",COUNTIFS(评分明细!$C:$C,A15,评分明细!$X:$X,">=60")) -> 0 | F15: =IF(B15=0,"",COUNTIFS(评分明细!$C:$C,A15,评分明细!$X:$X,">=80")) -> 0 | H15: 清结算组 | I15: 支付事业部 | J15: =IF(H15="","",IF(I15="",COUNTIFS(评分明细!$D:$D,H15,评分明细!$X:$X,"<>"),COUNTIFS(评分明细!$D:$D,H15,评分明细!$C:$C,I15,评分明细!$X:$X,"<>"))) -> 0 | K15: =IF(J15=0,"",IF(I15="",ROUND(AVERAGEIFS(评分明细!$X:$X,评分明细!$D:$D,H15,评分明细!$X:$X,"<>"),1),ROUND(AVERAGEIFS(评分明细!$X:$X,评分明细!$D:$D,H15,评分明细!$C:$C,I15,评分明细!$X:$X,"<>"),1))) -> 0 | L15: =IF(K15="","",ROUND(100-K15,1)) -> 0 | M15: =IF(J15=0,"",IF(I15="",COUNTIFS(评分明细!$D:$D,H15,评分明细!$X:$X,">=60"),COUNTIFS(评分明细!$D:$D,H15,评分明细!$C:$C,I15,评分明细!$X:$X,">=60"))) -> 0 | N15: =IF(J15=0,"",IF(I15="",COUNTIFS(评分明细!$D:$D,H15,评分明细!$X:$X,">=80"),COUNTIFS(评分明细!$D:$D,H15,评分明细!$C:$C,I15,评分明细!$X:$X,">=80"))) -> 0
A16: 数据平台主管 | B16: =IF(A16="","",COUNTIFS(评分明细!$C:$C,A16,评分明细!$X:$X,"<>")) -> 0 | C16: =IF(B16=0,"",ROUND(AVERAGEIFS(评分明细!$X:$X,评分明细!$C:$C,A16,评分明细!$X:$X,"<>"),1)) -> 0 | D16: =IF(C16="","",ROUND(100-C16,1)) -> 0 | E16: =IF(B16=0,"",COUNTIFS(评分明细!$C:$C,A16,评分明细!$X:$X,">=60")) -> 0 | F16: =IF(B16=0,"",COUNTIFS(评分明细!$C:$C,A16,评分明细!$X:$X,">=80")) -> 0 | H16: 营销平台组 | I16: 增长事业部 | J16: =IF(H16="","",IF(I16="",COUNTIFS(评分明细!$D:$D,H16,评分明细!$X:$X,"<>"),COUNTIFS(评分明细!$D:$D,H16,评分明细!$C:$C,I16,评分明细!$X:$X,"<>"))) -> 0 | K16: =IF(J16=0,"",IF(I16="",ROUND(AVERAGEIFS(评分明细!$X:$X,评分明细!$D:$D,H16,评分明细!$X:$X,"<>"),1),ROUND(AVERAGEIFS(评分明细!$X:$X,评分明细!$D:$D,H16,评分明细!$C:$C,I16,评分明细!$X:$X,"<>"),1))) -> 0 | L16: =IF(K16="","",ROUND(100-K16,1)) -> 0 | M16: =IF(J16=0,"",IF(I16="",COUNTIFS(评分明细!$D:$D,H16,评分明细!$X:$X,">=60"),COUNTIFS(评分明细!$D:$D,H16,评分明细!$C:$C,I16,评分明细!$X:$X,">=60"))) -> 0 | N16: =IF(J16=0,"",IF(I16="",COUNTIFS(评分明细!$D:$D,H16,评分明细!$X:$X,">=80"),COUNTIFS(评分明细!$D:$D,H16,评分明细!$C:$C,I16,评分明细!$X:$X,">=80"))) -> 0
A17: 国际化平台主管 | B17: =IF(A17="","",COUNTIFS(评分明细!$C:$C,A17,评分明细!$X:$X,"<>")) -> 0 | C17: =IF(B17=0,"",ROUND(AVERAGEIFS(评分明细!$X:$X,评分明细!$C:$C,A17,评分明细!$X:$X,"<>"),1)) -> 0 | D17: =IF(C17="","",ROUND(100-C17,1)) -> 0 | E17: =IF(B17=0,"",COUNTIFS(评分明细!$C:$C,A17,评分明细!$X:$X,">=60")) -> 0 | F17: =IF(B17=0,"",COUNTIFS(评分明细!$C:$C,A17,评分明细!$X:$X,">=80")) -> 0 | H17: 数据基础组 | I17: 数据平台主管 | J17: =IF(H17="","",IF(I17="",COUNTIFS(评分明细!$D:$D,H17,评分明细!$X:$X,"<>"),COUNTIFS(评分明细!$D:$D,H17,评分明细!$C:$C,I17,评分明细!$X:$X,"<>"))) -> 0 | K17: =IF(J17=0,"",IF(I17="",ROUND(AVERAGEIFS(评分明细!$X:$X,评分明细!$D:$D,H17,评分明细!$X:$X,"<>"),1),ROUND(AVERAGEIFS(评分明细!$X:$X,评分明细!$D:$D,H17,评分明细!$C:$C,I17,评分明细!$X:$X,"<>"),1))) -> 0 | L17: =IF(K17="","",ROUND(100-K17,1)) -> 0 | M17: =IF(J17=0,"",IF(I17="",COUNTIFS(评分明细!$D:$D,H17,评分明细!$X:$X,">=60"),COUNTIFS(评分明细!$D:$D,H17,评分明细!$C:$C,I17,评分明细!$X:$X,">=60"))) -> 0 | N17: =IF(J17=0,"",IF(I17="",COUNTIFS(评分明细!$D:$D,H17,评分明细!$X:$X,">=80"),COUNTIFS(评分明细!$D:$D,H17,评分明细!$C:$C,I17,评分明细!$X:$X,">=80"))) -> 0
B18: =IF(A18="","",COUNTIFS(评分明细!$C:$C,A18,评分明细!$X:$X,"<>")) -> 0 | C18: =IF(B18=0,"",ROUND(AVERAGEIFS(评分明细!$X:$X,评分明细!$C:$C,A18,评分明细!$X:$X,"<>"),1)) -> 0 | D18: =IF(C18="","",ROUND(100-C18,1)) -> 0 | E18: =IF(B18=0,"",COUNTIFS(评分明细!$C:$C,A18,评分明细!$X:$X,">=60")) -> 0 | F18: =IF(B18=0,"",COUNTIFS(评分明细!$C:$C,A18,评分明细!$X:$X,">=80")) -> 0 | H18: 开放平台组 | I18: 国际化平台主管 | J18: =IF(H18="","",IF(I18="",COUNTIFS(评分明细!$D:$D,H18,评分明细!$X:$X,"<>"),COUNTIFS(评分明细!$D:$D,H18,评分明细!$C:$C,I18,评分明细!$X:$X,"<>"))) -> 0 | K18: =IF(J18=0,"",IF(I18="",ROUND(AVERAGEIFS(评分明细!$X:$X,评分明细!$D:$D,H18,评分明细!$X:$X,"<>"),1),ROUND(AVERAGEIFS(评分明细!$X:$X,评分明细!$D:$D,H18,评分明细!$C:$C,I18,评分明细!$X:$X,"<>"),1))) -> 0 | L18: =IF(K18="","",ROUND(100-K18,1)) -> 0 | M18: =IF(J18=0,"",IF(I18="",COUNTIFS(评分明细!$D:$D,H18,评分明细!$X:$X,">=60"),COUNTIFS(评分明细!$D:$D,H18,评分明细!$C:$C,I18,评分明细!$X:$X,">=60"))) -> 0 | N18: =IF(J18=0,"",IF(I18="",COUNTIFS(评分明细!$D:$D,H18,评分明细!$X:$X,">=80"),COUNTIFS(评分明细!$D:$D,H18,评分明细!$C:$C,I18,评分明细!$X:$X,">=80"))) -> 0
B19: =IF(A19="","",COUNTIFS(评分明细!$C:$C,A19,评分明细!$X:$X,"<>")) -> 0 | C19: =IF(B19=0,"",ROUND(AVERAGEIFS(评分明细!$X:$X,评分明细!$C:$C,A19,评分明细!$X:$X,"<>"),1)) -> 0 | D19: =IF(C19="","",ROUND(100-C19,1)) -> 0 | E19: =IF(B19=0,"",COUNTIFS(评分明细!$C:$C,A19,评分明细!$X:$X,">=60")) -> 0 | F19: =IF(B19=0,"",COUNTIFS(评分明细!$C:$C,A19,评分明细!$X:$X,">=80")) -> 0 | J19: =IF(H19="","",IF(I19="",COUNTIFS(评分明细!$D:$D,H19,评分明细!$X:$X,"<>"),COUNTIFS(评分明细!$D:$D,H19,评分明细!$C:$C,I19,评分明细!$X:$X,"<>"))) -> 0 | K19: =IF(J19=0,"",IF(I19="",ROUND(AVERAGEIFS(评分明细!$X:$X,评分明细!$D:$D,H19,评分明细!$X:$X,"<>"),1),ROUND(AVERAGEIFS(评分明细!$X:$X,评分明细!$D:$D,H19,评分明细!$C:$C,I19,评分明细!$X:$X,"<>"),1))) -> 0 | L19: =IF(K19="","",ROUND(100-K19,1)) -> 0 | M19: =IF(J19=0,"",IF(I19="",COUNTIFS(评分明细!$D:$D,H19,评分明细!$X:$X,">=60"),COUNTIFS(评分明细!$D:$D,H19,评分明细!$C:$C,I19,评分明细!$X:$X,">=60"))) -> 0 | N19: =IF(J19=0,"",IF(I19="",COUNTIFS(评分明细!$D:$D,H19,评分明细!$X:$X,">=80"),COUNTIFS(评分明细!$D:$D,H19,评分明细!$C:$C,I19,评分明细!$X:$X,">=80"))) -> 0
B20: =IF(A20="","",COUNTIFS(评分明细!$C:$C,A20,评分明细!$X:$X,"<>")) -> 0 | C20: =IF(B20=0,"",ROUND(AVERAGEIFS(评分明细!$X:$X,评分明细!$C:$C,A20,评分明细!$X:$X,"<>"),1)) -> 0 | D20: =IF(C20="","",ROUND(100-C20,1)) -> 0 | E20: =IF(B20=0,"",COUNTIFS(评分明细!$C:$C,A20,评分明细!$X:$X,">=60")) -> 0 | F20: =IF(B20=0,"",COUNTIFS(评分明细!$C:$C,A20,评分明细!$X:$X,">=80")) -> 0 | J20: =IF(H20="","",IF(I20="",COUNTIFS(评分明细!$D:$D,H20,评分明细!$X:$X,"<>"),COUNTIFS(评分明细!$D:$D,H20,评分明细!$C:$C,I20,评分明细!$X:$X,"<>"))) -> 0 | K20: =IF(J20=0,"",IF(I20="",ROUND(AVERAGEIFS(评分明细!$X:$X,评分明细!$D:$D,H20,评分明细!$X:$X,"<>"),1),ROUND(AVERAGEIFS(评分明细!$X:$X,评分明细!$D:$D,H20,评分明细!$C:$C,I20,评分明细!$X:$X,"<>"),1))) -> 0 | L20: =IF(K20="","",ROUND(100-K20,1)) -> 0 | M20: =IF(J20=0,"",IF(I20="",COUNTIFS(评分明细!$D:$D,H20,评分明细!$X:$X,">=60"),COUNTIFS(评分明细!$D:$D,H20,评分明细!$C:$C,I20,评分明细!$X:$X,">=60"))) -> 0 | N20: =IF(J20=0,"",IF(I20="",COUNTIFS(评分明细!$D:$D,H20,评分明细!$X:$X,">=80"),COUNTIFS(评分明细!$D:$D,H20,评分明细!$C:$C,I20,评分明细!$X:$X,">=80"))) -> 0
B21: =IF(A21="","",COUNTIFS(评分明细!$C:$C,A21,评分明细!$X:$X,"<>")) -> 0 | C21: =IF(B21=0,"",ROUND(AVERAGEIFS(评分明细!$X:$X,评分明细!$C:$C,A21,评分明细!$X:$X,"<>"),1)) -> 0 | D21: =IF(C21="","",ROUND(100-C21,1)) -> 0 | E21: =IF(B21=0,"",COUNTIFS(评分明细!$C:$C,A21,评分明细!$X:$X,">=60")) -> 0 | F21: =IF(B21=0,"",COUNTIFS(评分明细!$C:$C,A21,评分明细!$X:$X,">=80")) -> 0 | J21: =IF(H21="","",IF(I21="",COUNTIFS(评分明细!$D:$D,H21,评分明细!$X:$X,"<>"),COUNTIFS(评分明细!$D:$D,H21,评分明细!$C:$C,I21,评分明细!$X:$X,"<>"))) -> 0 | K21: =IF(J21=0,"",IF(I21="",ROUND(AVERAGEIFS(评分明细!$X:$X,评分明细!$D:$D,H21,评分明细!$X:$X,"<>"),1),ROUND(AVERAGEIFS(评分明细!$X:$X,评分明细!$D:$D,H21,评分明细!$C:$C,I21,评分明细!$X:$X,"<>"),1))) -> 0 | L21: =IF(K21="","",ROUND(100-K21,1)) -> 0 | M21: =IF(J21=0,"",IF(I21="",COUNTIFS(评分明细!$D:$D,H21,评分明细!$X:$X,">=60"),COUNTIFS(评分明细!$D:$D,H21,评分明细!$C:$C,I21,评分明细!$X:$X,">=60"))) -> 0 | N21: =IF(J21=0,"",IF(I21="",COUNTIFS(评分明细!$D:$D,H21,评分明细!$X:$X,">=80"),COUNTIFS(评分明细!$D:$D,H21,评分明细!$C:$C,I21,评分明细!$X:$X,">=80"))) -> 0
B22: =IF(A22="","",COUNTIFS(评分明细!$C:$C,A22,评分明细!$X:$X,"<>")) -> 0 | C22: =IF(B22=0,"",ROUND(AVERAGEIFS(评分明细!$X:$X,评分明细!$C:$C,A22,评分明细!$X:$X,"<>"),1)) -> 0 | D22: =IF(C22="","",ROUND(100-C22,1)) -> 0 | E22: =IF(B22=0,"",COUNTIFS(评分明细!$C:$C,A22,评分明细!$X:$X,">=60")) -> 0 | F22: =IF(B22=0,"",COUNTIFS(评分明细!$C:$C,A22,评分明细!$X:$X,">=80")) -> 0 | J22: =IF(H22="","",IF(I22="",COUNTIFS(评分明细!$D:$D,H22,评分明细!$X:$X,"<>"),COUNTIFS(评分明细!$D:$D,H22,评分明细!$C:$C,I22,评分明细!$X:$X,"<>"))) -> 0 | K22: =IF(J22=0,"",IF(I22="",ROUND(AVERAGEIFS(评分明细!$X:$X,评分明细!$D:$D,H22,评分明细!$X:$X,"<>"),1),ROUND(AVERAGEIFS(评分明细!$X:$X,评分明细!$D:$D,H22,评分明细!$C:$C,I22,评分明细!$X:$X,"<>"),1))) -> 0 | L22: =IF(K22="","",ROUND(100-K22,1)) -> 0 | M22: =IF(J22=0,"",IF(I22="",COUNTIFS(评分明细!$D:$D,H22,评分明细!$X:$X,">=60"),COUNTIFS(评分明细!$D:$D,H22,评分明细!$C:$C,I22,评分明细!$X:$X,">=60"))) -> 0 | N22: =IF(J22=0,"",IF(I22="",COUNTIFS(评分明细!$D:$D,H22,评分明细!$X:$X,">=80"),COUNTIFS(评分明细!$D:$D,H22,评分明细!$C:$C,I22,评分明细!$X:$X,">=80"))) -> 0
B23: =IF(A23="","",COUNTIFS(评分明细!$C:$C,A23,评分明细!$X:$X,"<>")) -> 0 | C23: =IF(B23=0,"",ROUND(AVERAGEIFS(评分明细!$X:$X,评分明细!$C:$C,A23,评分明细!$X:$X,"<>"),1)) -> 0 | D23: =IF(C23="","",ROUND(100-C23,1)) -> 0 | E23: =IF(B23=0,"",COUNTIFS(评分明细!$C:$C,A23,评分明细!$X:$X,">=60")) -> 0 | F23: =IF(B23=0,"",COUNTIFS(评分明细!$C:$C,A23,评分明细!$X:$X,">=80")) -> 0 | J23: =IF(H23="","",IF(I23="",COUNTIFS(评分明细!$D:$D,H23,评分明细!$X:$X,"<>"),COUNTIFS(评分明细!$D:$D,H23,评分明细!$C:$C,I23,评分明细!$X:$X,"<>"))) -> 0 | K23: =IF(J23=0,"",IF(I23="",ROUND(AVERAGEIFS(评分明细!$X:$X,评分明细!$D:$D,H23,评分明细!$X:$X,"<>"),1),ROUND(AVERAGEIFS(评分明细!$X:$X,评分明细!$D:$D,H23,评分明细!$C:$C,I23,评分明细!$X:$X,"<>"),1))) -> 0 | L23: =IF(K23="","",ROUND(100-K23,1)) -> 0 | M23: =IF(J23=0,"",IF(I23="",COUNTIFS(评分明细!$D:$D,H23,评分明细!$X:$X,">=60"),COUNTIFS(评分明细!$D:$D,H23,评分明细!$C:$C,I23,评分明细!$X:$X,">=60"))) -> 0 | N23: =IF(J23=0,"",IF(I23="",COUNTIFS(评分明细!$D:$D,H23,评分明细!$X:$X,">=80"),COUNTIFS(评分明细!$D:$D,H23,评分明细!$C:$C,I23,评分明细!$X:$X,">=80"))) -> 0
B24: =IF(A24="","",COUNTIFS(评分明细!$C:$C,A24,评分明细!$X:$X,"<>")) -> 0 | C24: =IF(B24=0,"",ROUND(AVERAGEIFS(评分明细!$X:$X,评分明细!$C:$C,A24,评分明细!$X:$X,"<>"),1)) -> 0 | D24: =IF(C24="","",ROUND(100-C24,1)) -> 0 | E24: =IF(B24=0,"",COUNTIFS(评分明细!$C:$C,A24,评分明细!$X:$X,">=60")) -> 0 | F24: =IF(B24=0,"",COUNTIFS(评分明细!$C:$C,A24,评分明细!$X:$X,">=80")) -> 0 | J24: =IF(H24="","",IF(I24="",COUNTIFS(评分明细!$D:$D,H24,评分明细!$X:$X,"<>"),COUNTIFS(评分明细!$D:$D,H24,评分明细!$C:$C,I24,评分明细!$X:$X,"<>"))) -> 0 | K24: =IF(J24=0,"",IF(I24="",ROUND(AVERAGEIFS(评分明细!$X:$X,评分明细!$D:$D,H24,评分明细!$X:$X,"<>"),1),ROUND(AVERAGEIFS(评分明细!$X:$X,评分明细!$D:$D,H24,评分明细!$C:$C,I24,评分明细!$X:$X,"<>"),1))) -> 0 | L24: =IF(K24="","",ROUND(100-K24,1)) -> 0 | M24: =IF(J24=0,"",IF(I24="",COUNTIFS(评分明细!$D:$D,H24,评分明细!$X:$X,">=60"),COUNTIFS(评分明细!$D:$D,H24,评分明细!$C:$C,I24,评分明细!$X:$X,">=60"))) -> 0 | N24: =IF(J24=0,"",IF(I24="",COUNTIFS(评分明细!$D:$D,H24,评分明细!$X:$X,">=80"),COUNTIFS(评分明细!$D:$D,H24,评分明细!$C:$C,I24,评分明细!$X:$X,">=80"))) -> 0
B25: =IF(A25="","",COUNTIFS(评分明细!$C:$C,A25,评分明细!$X:$X,"<>")) -> 0 | C25: =IF(B25=0,"",ROUND(AVERAGEIFS(评分明细!$X:$X,评分明细!$C:$C,A25,评分明细!$X:$X,"<>"),1)) -> 0 | D25: =IF(C25="","",ROUND(100-C25,1)) -> 0 | E25: =IF(B25=0,"",COUNTIFS(评分明细!$C:$C,A25,评分明细!$X:$X,">=60")) -> 0 | F25: =IF(B25=0,"",COUNTIFS(评分明细!$C:$C,A25,评分明细!$X:$X,">=80")) -> 0 | J25: =IF(H25="","",IF(I25="",COUNTIFS(评分明细!$D:$D,H25,评分明细!$X:$X,"<>"),COUNTIFS(评分明细!$D:$D,H25,评分明细!$C:$C,I25,评分明细!$X:$X,"<>"))) -> 0 | K25: =IF(J25=0,"",IF(I25="",ROUND(AVERAGEIFS(评分明细!$X:$X,评分明细!$D:$D,H25,评分明细!$X:$X,"<>"),1),ROUND(AVERAGEIFS(评分明细!$X:$X,评分明细!$D:$D,H25,评分明细!$C:$C,I25,评分明细!$X:$X,"<>"),1))) -> 0 | L25: =IF(K25="","",ROUND(100-K25,1)) -> 0 | M25: =IF(J25=0,"",IF(I25="",COUNTIFS(评分明细!$D:$D,H25,评分明细!$X:$X,">=60"),COUNTIFS(评分明细!$D:$D,H25,评分明细!$C:$C,I25,评分明细!$X:$X,">=60"))) -> 0 | N25: =IF(J25=0,"",IF(I25="",COUNTIFS(评分明细!$D:$D,H25,评分明细!$X:$X,">=80"),COUNTIFS(评分明细!$D:$D,H25,评分明细!$C:$C,I25,评分明细!$X:$X,">=80"))) -> 0
B26: =IF(A26="","",COUNTIFS(评分明细!$C:$C,A26,评分明细!$X:$X,"<>")) -> 0 | C26: =IF(B26=0,"",ROUND(AVERAGEIFS(评分明细!$X:$X,评分明细!$C:$C,A26,评分明细!$X:$X,"<>"),1)) -> 0 | D26: =IF(C26="","",ROUND(100-C26,1)) -> 0 | E26: =IF(B26=0,"",COUNTIFS(评分明细!$C:$C,A26,评分明细!$X:$X,">=60")) -> 0 | F26: =IF(B26=0,"",COUNTIFS(评分明细!$C:$C,A26,评分明细!$X:$X,">=80")) -> 0 | J26: =IF(H26="","",IF(I26="",COUNTIFS(评分明细!$D:$D,H26,评分明细!$X:$X,"<>"),COUNTIFS(评分明细!$D:$D,H26,评分明细!$C:$C,I26,评分明细!$X:$X,"<>"))) -> 0 | K26: =IF(J26=0,"",IF(I26="",ROUND(AVERAGEIFS(评分明细!$X:$X,评分明细!$D:$D,H26,评分明细!$X:$X,"<>"),1),ROUND(AVERAGEIFS(评分明细!$X:$X,评分明细!$D:$D,H26,评分明细!$C:$C,I26,评分明细!$X:$X,"<>"),1))) -> 0 | L26: =IF(K26="","",ROUND(100-K26,1)) -> 0 | M26: =IF(J26=0,"",IF(I26="",COUNTIFS(评分明细!$D:$D,H26,评分明细!$X:$X,">=60"),COUNTIFS(评分明细!$D:$D,H26,评分明细!$C:$C,I26,评分明细!$X:$X,">=60"))) -> 0 | N26: =IF(J26=0,"",IF(I26="",COUNTIFS(评分明细!$D:$D,H26,评分明细!$X:$X,">=80"),COUNTIFS(评分明细!$D:$D,H26,评分明细!$C:$C,I26,评分明细!$X:$X,">=80"))) -> 0
B27: =IF(A27="","",COUNTIFS(评分明细!$C:$C,A27,评分明细!$X:$X,"<>")) -> 0 | C27: =IF(B27=0,"",ROUND(AVERAGEIFS(评分明细!$X:$X,评分明细!$C:$C,A27,评分明细!$X:$X,"<>"),1)) -> 0 | D27: =IF(C27="","",ROUND(100-C27,1)) -> 0 | E27: =IF(B27=0,"",COUNTIFS(评分明细!$C:$C,A27,评分明细!$X:$X,">=60")) -> 0 | F27: =IF(B27=0,"",COUNTIFS(评分明细!$C:$C,A27,评分明细!$X:$X,">=80")) -> 0 | J27: =IF(H27="","",IF(I27="",COUNTIFS(评分明细!$D:$D,H27,评分明细!$X:$X,"<>"),COUNTIFS(评分明细!$D:$D,H27,评分明细!$C:$C,I27,评分明细!$X:$X,"<>"))) -> 0 | K27: =IF(J27=0,"",IF(I27="",ROUND(AVERAGEIFS(评分明细!$X:$X,评分明细!$D:$D,H27,评分明细!$X:$X,"<>"),1),ROUND(AVERAGEIFS(评分明细!$X:$X,评分明细!$D:$D,H27,评分明细!$C:$C,I27,评分明细!$X:$X,"<>"),1))) -> 0 | L27: =IF(K27="","",ROUND(100-K27,1)) -> 0 | M27: =IF(J27=0,"",IF(I27="",COUNTIFS(评分明细!$D:$D,H27,评分明细!$X:$X,">=60"),COUNTIFS(评分明细!$D:$D,H27,评分明细!$C:$C,I27,评分明细!$X:$X,">=60"))) -> 0 | N27: =IF(J27=0,"",IF(I27="",COUNTIFS(评分明细!$D:$D,H27,评分明细!$X:$X,">=80"),COUNTIFS(评分明细!$D:$D,H27,评分明细!$C:$C,I27,评分明细!$X:$X,">=80"))) -> 0
B28: =IF(A28="","",COUNTIFS(评分明细!$C:$C,A28,评分明细!$X:$X,"<>")) -> 0 | C28: =IF(B28=0,"",ROUND(AVERAGEIFS(评分明细!$X:$X,评分明细!$C:$C,A28,评分明细!$X:$X,"<>"),1)) -> 0 | D28: =IF(C28="","",ROUND(100-C28,1)) -> 0 | E28: =IF(B28=0,"",COUNTIFS(评分明细!$C:$C,A28,评分明细!$X:$X,">=60")) -> 0 | F28: =IF(B28=0,"",COUNTIFS(评分明细!$C:$C,A28,评分明细!$X:$X,">=80")) -> 0 | J28: =IF(H28="","",IF(I28="",COUNTIFS(评分明细!$D:$D,H28,评分明细!$X:$X,"<>"),COUNTIFS(评分明细!$D:$D,H28,评分明细!$C:$C,I28,评分明细!$X:$X,"<>"))) -> 0 | K28: =IF(J28=0,"",IF(I28="",ROUND(AVERAGEIFS(评分明细!$X:$X,评分明细!$D:$D,H28,评分明细!$X:$X,"<>"),1),ROUND(AVERAGEIFS(评分明细!$X:$X,评分明细!$D:$D,H28,评分明细!$C:$C,I28,评分明细!$X:$X,"<>"),1))) -> 0 | L28: =IF(K28="","",ROUND(100-K28,1)) -> 0 | M28: =IF(J28=0,"",IF(I28="",COUNTIFS(评分明细!$D:$D,H28,评分明细!$X:$X,">=60"),COUNTIFS(评分明细!$D:$D,H28,评分明细!$C:$C,I28,评分明细!$X:$X,">=60"))) -> 0 | N28: =IF(J28=0,"",IF(I28="",COUNTIFS(评分明细!$D:$D,H28,评分明细!$X:$X,">=80"),COUNTIFS(评分明细!$D:$D,H28,评分明细!$C:$C,I28,评分明细!$X:$X,">=80"))) -> 0
B29: =IF(A29="","",COUNTIFS(评分明细!$C:$C,A29,评分明细!$X:$X,"<>")) -> 0 | C29: =IF(B29=0,"",ROUND(AVERAGEIFS(评分明细!$X:$X,评分明细!$C:$C,A29,评分明细!$X:$X,"<>"),1)) -> 0 | D29: =IF(C29="","",ROUND(100-C29,1)) -> 0 | E29: =IF(B29=0,"",COUNTIFS(评分明细!$C:$C,A29,评分明细!$X:$X,">=60")) -> 0 | F29: =IF(B29=0,"",COUNTIFS(评分明细!$C:$C,A29,评分明细!$X:$X,">=80")) -> 0 | J29: =IF(H29="","",IF(I29="",COUNTIFS(评分明细!$D:$D,H29,评分明细!$X:$X,"<>"),COUNTIFS(评分明细!$D:$D,H29,评分明细!$C:$C,I29,评分明细!$X:$X,"<>"))) -> 0 | K29: =IF(J29=0,"",IF(I29="",ROUND(AVERAGEIFS(评分明细!$X:$X,评分明细!$D:$D,H29,评分明细!$X:$X,"<>"),1),ROUND(AVERAGEIFS(评分明细!$X:$X,评分明细!$D:$D,H29,评分明细!$C:$C,I29,评分明细!$X:$X,"<>"),1))) -> 0 | L29: =IF(K29="","",ROUND(100-K29,1)) -> 0 | M29: =IF(J29=0,"",IF(I29="",COUNTIFS(评分明细!$D:$D,H29,评分明细!$X:$X,">=60"),COUNTIFS(评分明细!$D:$D,H29,评分明细!$C:$C,I29,评分明细!$X:$X,">=60"))) -> 0 | N29: =IF(J29=0,"",IF(I29="",COUNTIFS(评分明细!$D:$D,H29,评分明细!$X:$X,">=80"),COUNTIFS(评分明细!$D:$D,H29,评分明细!$C:$C,I29,评分明细!$X:$X,">=80"))) -> 0
B30: =IF(A30="","",COUNTIFS(评分明细!$C:$C,A30,评分明细!$X:$X,"<>")) -> 0 | C30: =IF(B30=0,"",ROUND(AVERAGEIFS(评分明细!$X:$X,评分明细!$C:$C,A30,评分明细!$X:$X,"<>"),1)) -> 0 | D30: =IF(C30="","",ROUND(100-C30,1)) -> 0 | E30: =IF(B30=0,"",COUNTIFS(评分明细!$C:$C,A30,评分明细!$X:$X,">=60")) -> 0 | F30: =IF(B30=0,"",COUNTIFS(评分明细!$C:$C,A30,评分明细!$X:$X,">=80")) -> 0 | J30: =IF(H30="","",IF(I30="",COUNTIFS(评分明细!$D:$D,H30,评分明细!$X:$X,"<>"),COUNTIFS(评分明细!$D:$D,H30,评分明细!$C:$C,I30,评分明细!$X:$X,"<>"))) -> 0 | K30: =IF(J30=0,"",IF(I30="",ROUND(AVERAGEIFS(评分明细!$X:$X,评分明细!$D:$D,H30,评分明细!$X:$X,"<>"),1),ROUND(AVERAGEIFS(评分明细!$X:$X,评分明细!$D:$D,H30,评分明细!$C:$C,I30,评分明细!$X:$X,"<>"),1))) -> 0 | L30: =IF(K30="","",ROUND(100-K30,1)) -> 0 | M30: =IF(J30=0,"",IF(I30="",COUNTIFS(评分明细!$D:$D,H30,评分明细!$X:$X,">=60"),COUNTIFS(评分明细!$D:$D,H30,评分明细!$C:$C,I30,评分明细!$X:$X,">=60"))) -> 0 | N30: =IF(J30=0,"",IF(I30="",COUNTIFS(评分明细!$D:$D,H30,评分明细!$X:$X,">=80"),COUNTIFS(评分明细!$D:$D,H30,评分明细!$C:$C,I30,评分明细!$X:$X,">=80"))) -> 0
... B43: =IF(A43="","",COUNTIFS(评分明细!$C:$C,A43,评分明细!$X:$X,"<>")) -> 0 | C43: =IF(B43=0,"",ROUND(AVERAGEIFS(评分明细!$X:$X,评分明细!$C:$C,A43,评分明细!$X:$X,"<>"),1)) -> 0 | D43: =IF(C43="","",ROUND(100-C43,1)) -> 0 | E43: =IF(B43=0,"",COUNTIFS(评分明细!$C:$C,A43,评分明细!$X:$X,">=60")) -> 0 | F43: =IF(B43=0,"",COUNTIFS(评分明细!$C:$C,A43,评分明细!$X:$X,">=80")) -> 0 | J43: =IF(H43="","",IF(I43="",COUNTIFS(评分明细!$D:$D,H43,评分明细!$X:$X,"<>"),COUNTIFS(评分明细!$D:$D,H43,评分明细!$C:$C,I43,评分明细!$X:$X,"<>"))) -> 0 | K43: =IF(J43=0,"",IF(I43="",ROUND(AVERAGEIFS(评分明细!$X:$X,评分明细!$D:$D,H43,评分明细!$X:$X,"<>"),1),ROUND(AVERAGEIFS(评分明细!$X:$X,评分明细!$D:$D,H43,评分明细!$C:$C,I43,评分明细!$X:$X,"<>"),1))) -> 0 | L43: =IF(K43="","",ROUND(100-K43,1)) -> 0 | M43: =IF(J43=0,"",IF(I43="",COUNTIFS(评分明细!$D:$D,H43,评分明细!$X:$X,">=60"),COUNTIFS(评分明细!$D:$D,H43,评分明细!$C:$C,I43,评分明细!$X:$X,">=60"))) -> 0 | N43: =IF(J43=0,"",IF(I43="",COUNTIFS(评分明细!$D:$D,H43,评分明细!$X:$X,">=80"),COUNTIFS(评分明细!$D:$D,H43,评分明细!$C:$C,I43,评分明细!$X:$X,">=80"))) -> 0
J44: =IF(H44="","",IF(I44="",COUNTIFS(评分明细!$D:$D,H44,评分明细!$X:$X,"<>"),COUNTIFS(评分明细!$D:$D,H44,评分明细!$C:$C,I44,评分明细!$X:$X,"<>"))) -> 0 | K44: =IF(J44=0,"",IF(I44="",ROUND(AVERAGEIFS(评分明细!$X:$X,评分明细!$D:$D,H44,评分明细!$X:$X,"<>"),1),ROUND(AVERAGEIFS(评分明细!$X:$X,评分明细!$D:$D,H44,评分明细!$C:$C,I44,评分明细!$X:$X,"<>"),1))) -> 0 | L44: =IF(K44="","",ROUND(100-K44,1)) -> 0 | M44: =IF(J44=0,"",IF(I44="",COUNTIFS(评分明细!$D:$D,H44,评分明细!$X:$X,">=60"),COUNTIFS(评分明细!$D:$D,H44,评分明细!$C:$C,I44,评分明细!$X:$X,">=60"))) -> 0 | N44: =IF(J44=0,"",IF(I44="",COUNTIFS(评分明细!$D:$D,H44,评分明细!$X:$X,">=80"),COUNTIFS(评分明细!$D:$D,H44,评分明细!$C:$C,I44,评分明细!$X:$X,">=80"))) -> 0
J45: =IF(H45="","",IF(I45="",COUNTIFS(评分明细!$D:$D,H45,评分明细!$X:$X,"<>"),COUNTIFS(评分明细!$D:$D,H45,评分明细!$C:$C,I45,评分明细!$X:$X,"<>"))) -> 0 | K45: =IF(J45=0,"",IF(I45="",ROUND(AVERAGEIFS(评分明细!$X:$X,评分明细!$D:$D,H45,评分明细!$X:$X,"<>"),1),ROUND(AVERAGEIFS(评分明细!$X:$X,评分明细!$D:$D,H45,评分明细!$C:$C,I45,评分明细!$X:$X,"<>"),1))) -> 0 | L45: =IF(K45="","",ROUND(100-K45,1)) -> 0 | M45: =IF(J45=0,"",IF(I45="",COUNTIFS(评分明细!$D:$D,H45,评分明细!$X:$X,">=60"),COUNTIFS(评分明细!$D:$D,H45,评分明细!$C:$C,I45,评分明细!$X:$X,">=60"))) -> 0 | N45: =IF(J45=0,"",IF(I45="",COUNTIFS(评分明细!$D:$D,H45,评分明细!$X:$X,">=80"),COUNTIFS(评分明细!$D:$D,H45,评分明细!$C:$C,I45,评分明细!$X:$X,">=80"))) -> 0
J46: =IF(H46="","",IF(I46="",COUNTIFS(评分明细!$D:$D,H46,评分明细!$X:$X,"<>"),COUNTIFS(评分明细!$D:$D,H46,评分明细!$C:$C,I46,评分明细!$X:$X,"<>"))) -> 0 | K46: =IF(J46=0,"",IF(I46="",ROUND(AVERAGEIFS(评分明细!$X:$X,评分明细!$D:$D,H46,评分明细!$X:$X,"<>"),1),ROUND(AVERAGEIFS(评分明细!$X:$X,评分明细!$D:$D,H46,评分明细!$C:$C,I46,评分明细!$X:$X,"<>"),1))) -> 0 | L46: =IF(K46="","",ROUND(100-K46,1)) -> 0 | M46: =IF(J46=0,"",IF(I46="",COUNTIFS(评分明细!$D:$D,H46,评分明细!$X:$X,">=60"),COUNTIFS(评分明细!$D:$D,H46,评分明细!$C:$C,I46,评分明细!$X:$X,">=60"))) -> 0 | N46: =IF(J46=0,"",IF(I46="",COUNTIFS(评分明细!$D:$D,H46,评分明细!$X:$X,">=80"),COUNTIFS(评分明细!$D:$D,H46,评分明细!$C:$C,I46,评分明细!$X:$X,">=80"))) -> 0
J47: =IF(H47="","",IF(I47="",COUNTIFS(评分明细!$D:$D,H47,评分明细!$X:$X,"<>"),COUNTIFS(评分明细!$D:$D,H47,评分明细!$C:$C,I47,评分明细!$X:$X,"<>"))) -> 0 | K47: =IF(J47=0,"",IF(I47="",ROUND(AVERAGEIFS(评分明细!$X:$X,评分明细!$D:$D,H47,评分明细!$X:$X,"<>"),1),ROUND(AVERAGEIFS(评分明细!$X:$X,评分明细!$D:$D,H47,评分明细!$C:$C,I47,评分明细!$X:$X,"<>"),1))) -> 0 | L47: =IF(K47="","",ROUND(100-K47,1)) -> 0 | M47: =IF(J47=0,"",IF(I47="",COUNTIFS(评分明细!$D:$D,H47,评分明细!$X:$X,">=60"),COUNTIFS(评分明细!$D:$D,H47,评分明细!$C:$C,I47,评分明细!$X:$X,">=60"))) -> 0 | N47: =IF(J47=0,"",IF(I47="",COUNTIFS(评分明细!$D:$D,H47,评分明细!$X:$X,">=80"),COUNTIFS(评分明细!$D:$D,H47,评分明细!$C:$C,I47,评分明细!$X:$X,">=80"))) -> 0
J48: =IF(H48="","",IF(I48="",COUNTIFS(评分明细!$D:$D,H48,评分明细!$X:$X,"<>"),COUNTIFS(评分明细!$D:$D,H48,评分明细!$C:$C,I48,评分明细!$X:$X,"<>"))) -> 0 | K48: =IF(J48=0,"",IF(I48="",ROUND(AVERAGEIFS(评分明细!$X:$X,评分明细!$D:$D,H48,评分明细!$X:$X,"<>"),1),ROUND(AVERAGEIFS(评分明细!$X:$X,评分明细!$D:$D,H48,评分明细!$C:$C,I48,评分明细!$X:$X,"<>"),1))) -> 0 | L48: =IF(K48="","",ROUND(100-K48,1)) -> 0 | M48: =IF(J48=0,"",IF(I48="",COUNTIFS(评分明细!$D:$D,H48,评分明细!$X:$X,">=60"),COUNTIFS(评分明细!$D:$D,H48,评分明细!$C:$C,I48,评分明细!$X:$X,">=60"))) -> 0 | N48: =IF(J48=0,"",IF(I48="",COUNTIFS(评分明细!$D:$D,H48,评分明细!$X:$X,">=80"),COUNTIFS(评分明细!$D:$D,H48,评分明细!$C:$C,I48,评分明细!$X:$X,">=80"))) -> 0
J49: =IF(H49="","",IF(I49="",COUNTIFS(评分明细!$D:$D,H49,评分明细!$X:$X,"<>"),COUNTIFS(评分明细!$D:$D,H49,评分明细!$C:$C,I49,评分明细!$X:$X,"<>"))) -> 0 | K49: =IF(J49=0,"",IF(I49="",ROUND(AVERAGEIFS(评分明细!$X:$X,评分明细!$D:$D,H49,评分明细!$X:$X,"<>"),1),ROUND(AVERAGEIFS(评分明细!$X:$X,评分明细!$D:$D,H49,评分明细!$C:$C,I49,评分明细!$X:$X,"<>"),1))) -> 0 | L49: =IF(K49="","",ROUND(100-K49,1)) -> 0 | M49: =IF(J49=0,"",IF(I49="",COUNTIFS(评分明细!$D:$D,H49,评分明细!$X:$X,">=60"),COUNTIFS(评分明细!$D:$D,H49,评分明细!$C:$C,I49,评分明细!$X:$X,">=60"))) -> 0 | N49: =IF(J49=0,"",IF(I49="",COUNTIFS(评分明细!$D:$D,H49,评分明细!$X:$X,">=80"),COUNTIFS(评分明细!$D:$D,H49,评分明细!$C:$C,I49,评分明细!$X:$X,">=80"))) -> 0
J50: =IF(H50="","",IF(I50="",COUNTIFS(评分明细!$D:$D,H50,评分明细!$X:$X,"<>"),COUNTIFS(评分明细!$D:$D,H50,评分明细!$C:$C,I50,评分明细!$X:$X,"<>"))) -> 0 | K50: =IF(J50=0,"",IF(I50="",ROUND(AVERAGEIFS(评分明细!$X:$X,评分明细!$D:$D,H50,评分明细!$X:$X,"<>"),1),ROUND(AVERAGEIFS(评分明细!$X:$X,评分明细!$D:$D,H50,评分明细!$C:$C,I50,评分明细!$X:$X,"<>"),1))) -> 0 | L50: =IF(K50="","",ROUND(100-K50,1)) -> 0 | M50: =IF(J50=0,"",IF(I50="",COUNTIFS(评分明细!$D:$D,H50,评分明细!$X:$X,">=60"),COUNTIFS(评分明细!$D:$D,H50,评分明细!$C:$C,I50,评分明细!$X:$X,">=60"))) -> 0 | N50: =IF(J50=0,"",IF(I50="",COUNTIFS(评分明细!$D:$D,H50,评分明细!$X:$X,">=80"),COUNTIFS(评分明细!$D:$D,H50,评分明细!$C:$C,I50,评分明细!$X:$X,">=80"))) -> 0
J51: =IF(H51="","",IF(I51="",COUNTIFS(评分明细!$D:$D,H51,评分明细!$X:$X,"<>"),COUNTIFS(评分明细!$D:$D,H51,评分明细!$C:$C,I51,评分明细!$X:$X,"<>"))) -> 0 | K51: =IF(J51=0,"",IF(I51="",ROUND(AVERAGEIFS(评分明细!$X:$X,评分明细!$D:$D,H51,评分明细!$X:$X,"<>"),1),ROUND(AVERAGEIFS(评分明细!$X:$X,评分明细!$D:$D,H51,评分明细!$C:$C,I51,评分明细!$X:$X,"<>"),1))) -> 0 | L51: =IF(K51="","",ROUND(100-K51,1)) -> 0 | M51: =IF(J51=0,"",IF(I51="",COUNTIFS(评分明细!$D:$D,H51,评分明细!$X:$X,">=60"),COUNTIFS(评分明细!$D:$D,H51,评分明细!$C:$C,I51,评分明细!$X:$X,">=60"))) -> 0 | N51: =IF(J51=0,"",IF(I51="",COUNTIFS(评分明细!$D:$D,H51,评分明细!$X:$X,">=80"),COUNTIFS(评分明细!$D:$D,H51,评分明细!$C:$C,I51,评分明细!$X:$X,">=80"))) -> 0
J52: =IF(H52="","",IF(I52="",COUNTIFS(评分明细!$D:$D,H52,评分明细!$X:$X,"<>"),COUNTIFS(评分明细!$D:$D,H52,评分明细!$C:$C,I52,评分明细!$X:$X,"<>"))) -> 0 | K52: =IF(J52=0,"",IF(I52="",ROUND(AVERAGEIFS(评分明细!$X:$X,评分明细!$D:$D,H52,评分明细!$X:$X,"<>"),1),ROUND(AVERAGEIFS(评分明细!$X:$X,评分明细!$D:$D,H52,评分明细!$C:$C,I52,评分明细!$X:$X,"<>"),1))) -> 0 | L52: =IF(K52="","",ROUND(100-K52,1)) -> 0 | M52: =IF(J52=0,"",IF(I52="",COUNTIFS(评分明细!$D:$D,H52,评分明细!$X:$X,">=60"),COUNTIFS(评分明细!$D:$D,H52,评分明细!$C:$C,I52,评分明细!$X:$X,">=60"))) -> 0 | N52: =IF(J52=0,"",IF(I52="",COUNTIFS(评分明细!$D:$D,H52,评分明细!$X:$X,">=80"),COUNTIFS(评分明细!$D:$D,H52,评分明细!$C:$C,I52,评分明细!$X:$X,">=80"))) -> 0
J53: =IF(H53="","",IF(I53="",COUNTIFS(评分明细!$D:$D,H53,评分明细!$X:$X,"<>"),COUNTIFS(评分明细!$D:$D,H53,评分明细!$C:$C,I53,评分明细!$X:$X,"<>"))) -> 0 | K53: =IF(J53=0,"",IF(I53="",ROUND(AVERAGEIFS(评分明细!$X:$X,评分明细!$D:$D,H53,评分明细!$X:$X,"<>"),1),ROUND(AVERAGEIFS(评分明细!$X:$X,评分明细!$D:$D,H53,评分明细!$C:$C,I53,评分明细!$X:$X,"<>"),1))) -> 0 | L53: =IF(K53="","",ROUND(100-K53,1)) -> 0 | M53: =IF(J53=0,"",IF(I53="",COUNTIFS(评分明细!$D:$D,H53,评分明细!$X:$X,">=60"),COUNTIFS(评分明细!$D:$D,H53,评分明细!$C:$C,I53,评分明细!$X:$X,">=60"))) -> 0 | N53: =IF(J53=0,"",IF(I53="",COUNTIFS(评分明细!$D:$D,H53,评分明细!$X:$X,">=80"),COUNTIFS(评分明细!$D:$D,H53,评分明细!$C:$C,I53,评分明细!$X:$X,">=80"))) -> 0
J54: =IF(H54="","",IF(I54="",COUNTIFS(评分明细!$D:$D,H54,评分明细!$X:$X,"<>"),COUNTIFS(评分明细!$D:$D,H54,评分明细!$C:$C,I54,评分明细!$X:$X,"<>"))) -> 0 | K54: =IF(J54=0,"",IF(I54="",ROUND(AVERAGEIFS(评分明细!$X:$X,评分明细!$D:$D,H54,评分明细!$X:$X,"<>"),1),ROUND(AVERAGEIFS(评分明细!$X:$X,评分明细!$D:$D,H54,评分明细!$C:$C,I54,评分明细!$X:$X,"<>"),1))) -> 0 | L54: =IF(K54="","",ROUND(100-K54,1)) -> 0 | M54: =IF(J54=0,"",IF(I54="",COUNTIFS(评分明细!$D:$D,H54,评分明细!$X:$X,">=60"),COUNTIFS(评分明细!$D:$D,H54,评分明细!$C:$C,I54,评分明细!$X:$X,">=60"))) -> 0 | N54: =IF(J54=0,"",IF(I54="",COUNTIFS(评分明细!$D:$D,H54,评分明细!$X:$X,">=80"),COUNTIFS(评分明细!$D:$D,H54,评分明细!$C:$C,I54,评分明细!$X:$X,">=80"))) -> 0
...
